<?xml version="1.0" encoding="utf-8"?>
<!-- This URDF was automatically created by SolidWorks to URDF Exporter! Originally created by Stephen Brawner (brawner@gmail.com) 
     Commit Version: 1.6.0-4-g7f85cfe  Build Version: 1.6.7995.38578
     For more information, please see http://wiki.ros.org/sw_urdf_exporter -->
<robot
  name="Shuangzulun">
  <link
    name="base_link">
    <inertial>
      <origin
        xyz="-2.06685949717221E-06 0.0242691055965516 -3.19511749374861E-05"
        rpy="0 0 0" />
      <mass
        value="0.356780480322963" />
      <inertia
        ixx="0.00022945772142675"
        ixy="1.56227645579509E-09"
        ixz="1.10758177428464E-09"
        iyy="0.000289967073130902"
        iyz="5.54970300017836E-08"
        izz="0.000140635927790269" />
    </inertial>
    <visual>
      <origin
        xyz="0 0 0"
        rpy="0 0 0" />
      <geometry>
        <mesh
          filename="package://Shuangzulun/meshes/base_link.STL" />
      </geometry>
      <material
        name="">
        <color
          rgba="1 1 1 1" />
      </material>
    </visual>
    <collision>
      <origin
        xyz="0 0 0"
        rpy="0 0 0" />
      <geometry>
        <mesh
          filename="package://Shuangzulun/meshes/base_link.STL" />
      </geometry>
    </collision>
  </link>
  <link
    name="L_F_1">
    <inertial>
      <origin
        xyz="0.0200809690208486 0.00243813211080819 1.11022302462516E-16"
        rpy="0 0 0" />
      <mass
        value="0.0103010381319344" />
      <inertia
        ixx="7.46635077822692E-07"
        ixy="1.9067502731996E-08"
        ixz="4.76456032830544E-22"
        iyy="5.01527868596811E-06"
        iyz="1.24077091882954E-23"
        izz="4.31106087412847E-06" />
    </inertial>
    <visual>
      <origin
        xyz="0 0 0"
        rpy="0 0 0" />
      <geometry>
        <mesh
          filename="package://Shuangzulun/meshes/L_F_1.STL" />
      </geometry>
      <material
        name="">
        <color
          rgba="1 1 1 1" />
      </material>
    </visual>
    <collision>
      <origin
        xyz="0 0 0"
        rpy="0 0 0" />
      <geometry>
        <mesh
          filename="package://Shuangzulun/meshes/L_F_1.STL" />
      </geometry>
    </collision>
  </link>
  <joint
    name="L_F_1"
    type="continuous">
    <origin
      xyz="0.0665 -0.03 0.034"
      rpy="0 0.40283 -1.5708" />
    <parent
      link="base_link" />
    <child
      link="L_F_1" />
    <axis
      xyz="0 1 0" />
  </joint>
  <link
    name="L_F_2">
    <inertial>
      <origin
        xyz="0.0579756907615433 -0.00265632955087471 -1.1647088906247E-06"
        rpy="0 0 0" />
      <mass
        value="0.0152703665823153" />
      <inertia
        ixx="7.683764954588E-07"
        ixy="1.42961184690718E-08"
        ixz="1.17880192616912E-08"
        iyy="2.01064464712028E-05"
        iyz="4.16136337112369E-13"
        izz="1.94031525718367E-05" />
    </inertial>
    <visual>
      <origin
        xyz="0 0 0"
        rpy="0 0 0" />
      <geometry>
        <mesh
          filename="package://Shuangzulun/meshes/L_F_2.STL" />
      </geometry>
      <material
        name="">
        <color
          rgba="1 1 1 1" />
      </material>
    </visual>
    <collision>
      <origin
        xyz="0 0 0"
        rpy="0 0 0" />
      <geometry>
        <mesh
          filename="package://Shuangzulun/meshes/L_F_2.STL" />
      </geometry>
    </collision>
  </link>
  <joint
    name="L_F_2"
    type="continuous">
    <origin
      xyz="0.05 0.006 0"
      rpy="0 1.1791 3.1416" />
    <parent
      link="L_F_1" />
    <child
      link="L_F_2" />
    <axis
      xyz="0 1 0" />
  </joint>
  <link
    name="L_F_lun">
    <inertial>
      <origin
        xyz="-9.26299902122285E-06 0.0168802665650716 -1.04684400798541E-05"
        rpy="0 0 0" />
      <mass
        value="0.0382346146678116" />
      <inertia
        ixx="7.29689988825768E-06"
        ixy="-4.01191417658799E-10"
        ixz="-2.14386273828961E-09"
        iyy="1.22053148780522E-05"
        iyz="-4.53400492262894E-10"
        izz="7.29648214132153E-06" />
    </inertial>
    <visual>
      <origin
        xyz="0 0 0"
        rpy="0 0 0" />
      <geometry>
        <mesh
          filename="package://Shuangzulun/meshes/L_F_lun.STL" />
      </geometry>
      <material
        name="">
        <color
          rgba="0.298039215686275 0.298039215686275 0.298039215686275 1" />
      </material>
    </visual>
    <collision>
      <origin
        xyz="0 0 0"
        rpy="0 0 0" />
      <geometry>
        <mesh
          filename="package://Shuangzulun/meshes/L_F_lun.STL" />
      </geometry>
    </collision>
  </link>
  <joint
    name="L_F_lun"
    type="continuous">
    <origin
      xyz="0.105 -0.0055 0"
      rpy="0 0.18199 3.1416" />
    <parent
      link="L_F_2" />
    <child
      link="L_F_lun" />
    <axis
      xyz="0 1 0" />
  </joint>
  <link
    name="L_H_1">
    <inertial>
      <origin
        xyz="0.0200809690208485 -0.00256186788919183 9.71445146547012E-17"
        rpy="0 0 0" />
      <mass
        value="0.0103010381319344" />
      <inertia
        ixx="7.46635077822692E-07"
        ixy="1.90675027319959E-08"
        ixz="4.2351647362715E-22"
        iyy="5.01527868596811E-06"
        iyz="-5.79026428787119E-23"
        izz="4.31106087412847E-06" />
    </inertial>
    <visual>
      <origin
        xyz="0 0 0"
        rpy="0 0 0" />
      <geometry>
        <mesh
          filename="package://Shuangzulun/meshes/L_H_1.STL" />
      </geometry>
      <material
        name="">
        <color
          rgba="1 1 1 1" />
      </material>
    </visual>
    <collision>
      <origin
        xyz="0 0 0"
        rpy="0 0 0" />
      <geometry>
        <mesh
          filename="package://Shuangzulun/meshes/L_H_1.STL" />
      </geometry>
    </collision>
  </link>
  <joint
    name="L_H_1"
    type="continuous">
    <origin
      xyz="0.0725 0.03 0.034"
      rpy="0 0.4364 1.5708" />
    <parent
      link="base_link" />
    <child
      link="L_H_1" />
    <axis
      xyz="0 1 0" />
  </joint>
  <link
    name="L_H_2">
    <inertial>
      <origin
        xyz="0.0579756907615436 -0.00265632955087469 -1.16470889147818E-06"
        rpy="0 0 0" />
      <mass
        value="0.0152703665823153" />
      <inertia
        ixx="7.68376495458806E-07"
        ixy="1.42961184690763E-08"
        ixz="1.17880192616836E-08"
        iyy="2.01064464712029E-05"
        iyz="4.16136337023104E-13"
        izz="1.94031525718368E-05" />
    </inertial>
    <visual>
      <origin
        xyz="0 0 0"
        rpy="0 0 0" />
      <geometry>
        <mesh
          filename="package://Shuangzulun/meshes/L_H_2.STL" />
      </geometry>
      <material
        name="">
        <color
          rgba="1 1 1 1" />
      </material>
    </visual>
    <collision>
      <origin
        xyz="0 0 0"
        rpy="0 0 0" />
      <geometry>
        <mesh
          filename="package://Shuangzulun/meshes/L_H_2.STL" />
      </geometry>
    </collision>
  </link>
  <joint
    name="L_H_2"
    type="continuous">
    <origin
      xyz="0.05 0.001 0"
      rpy="0 1.1924 3.1416" />
    <parent
      link="L_H_1" />
    <child
      link="L_H_2" />
    <axis
      xyz="0 1 0" />
  </joint>
  <link
    name="L_H_lun">
    <inertial>
      <origin
        xyz="-0.0322462055063696 0.0948802665650716 -0.049638367129516"
        rpy="0 0 0" />
      <mass
        value="0.0382346146678116" />
      <inertia
        ixx="7.29689988825768E-06"
        ixy="-4.01191417658811E-10"
        ixz="-2.14386273828834E-09"
        iyy="1.22053148780522E-05"
        iyz="-4.53400492262732E-10"
        izz="7.29648214132153E-06" />
    </inertial>
    <visual>
      <origin
        xyz="0 0 0"
        rpy="0 0 0" />
      <geometry>
        <mesh
          filename="package://Shuangzulun/meshes/L_H_lun.STL" />
      </geometry>
      <material
        name="">
        <color
          rgba="0.298039215686275 0.298039215686275 0.298039215686275 1" />
      </material>
    </visual>
    <collision>
      <origin
        xyz="0 0 0"
        rpy="0 0 0" />
      <geometry>
        <mesh
          filename="package://Shuangzulun/meshes/L_H_lun.STL" />
      </geometry>
    </collision>
  </link>
  <joint
    name="L_H_lun"
    type="continuous">
    <origin
      xyz="0.063622 -0.0715 0.042308"
      rpy="0 -1.3504 0" />
    <parent
      link="L_H_2" />
    <child
      link="L_H_lun" />
    <axis
      xyz="0 1 0" />
  </joint>
  <link
    name="R_F_1">
    <inertial>
      <origin
        xyz="0.020080969020849 -0.00256186788919183 -6.24500451351651E-17"
        rpy="0 0 0" />
      <mass
        value="0.0103010381319344" />
      <inertia
        ixx="7.4663507782269E-07"
        ixy="1.9067502731996E-08"
        ixz="-6.88214269644119E-22"
        iyy="5.0152786859681E-06"
        iyz="-4.3802960298815E-22"
        izz="4.31106087412846E-06" />
    </inertial>
    <visual>
      <origin
        xyz="0 0 0"
        rpy="0 0 0" />
      <geometry>
        <mesh
          filename="package://Shuangzulun/meshes/R_F_1.STL" />
      </geometry>
      <material
        name="">
        <color
          rgba="1 1 1 1" />
      </material>
    </visual>
    <collision>
      <origin
        xyz="0 0 0"
        rpy="0 0 0" />
      <geometry>
        <mesh
          filename="package://Shuangzulun/meshes/R_F_1.STL" />
      </geometry>
    </collision>
  </link>
  <joint
    name="R_F_1"
    type="continuous">
    <origin
      xyz="-0.0725 -0.03 0.034"
      rpy="0 0.40283 -1.5708" />
    <parent
      link="base_link" />
    <child
      link="R_F_1" />
    <axis
      xyz="0 1 0" />
  </joint>
  <link
    name="R_F_2">
    <inertial>
      <origin
        xyz="0.0579756907615439 -0.00265632955087471 -1.16470889158227E-06"
        rpy="0 0 0" />
      <mass
        value="0.0152703665823153" />
      <inertia
        ixx="7.68376495458802E-07"
        ixy="1.42961184690755E-08"
        ixz="1.17880192616758E-08"
        iyy="2.01064464712029E-05"
        iyz="4.16136337061911E-13"
        izz="1.94031525718368E-05" />
    </inertial>
    <visual>
      <origin
        xyz="0 0 0"
        rpy="0 0 0" />
      <geometry>
        <mesh
          filename="package://Shuangzulun/meshes/R_F_2.STL" />
      </geometry>
      <material
        name="">
        <color
          rgba="1 1 1 1" />
      </material>
    </visual>
    <collision>
      <origin
        xyz="0 0 0"
        rpy="0 0 0" />
      <geometry>
        <mesh
          filename="package://Shuangzulun/meshes/R_F_2.STL" />
      </geometry>
    </collision>
  </link>
  <joint
    name="R_F_2"
    type="continuous">
    <origin
      xyz="0.05 0.001 0"
      rpy="0 1.1791 -3.1416" />
    <parent
      link="R_F_1" />
    <child
      link="R_F_2" />
    <axis
      xyz="0 1 0" />
  </joint>
  <link
    name="R_F_lun">
    <inertial>
      <origin
        xyz="1.66708806209094E-06 -0.0168802665650715 1.3878479958325E-05"
        rpy="0 0 0" />
      <mass
        value="0.0382346146678116" />
      <inertia
        ixx="7.29879580972196E-06"
        ixy="-7.22035508470689E-11"
        ixz="-4.57836061297952E-10"
        iyy="1.22053148780522E-05"
        iyz="-6.01093343182156E-10"
        izz="7.29458621985725E-06" />
    </inertial>
    <visual>
      <origin
        xyz="0 0 0"
        rpy="0 0 0" />
      <geometry>
        <mesh
          filename="package://Shuangzulun/meshes/R_F_lun.STL" />
      </geometry>
      <material
        name="">
        <color
          rgba="0.298039215686275 0.298039215686275 0.298039215686275 1" />
      </material>
    </visual>
    <collision>
      <origin
        xyz="0 0 0"
        rpy="0 0 0" />
      <geometry>
        <mesh
          filename="package://Shuangzulun/meshes/R_F_lun.STL" />
      </geometry>
    </collision>
  </link>
  <joint
    name="R_F_lun"
    type="continuous">
    <origin
      xyz="0.105 0.0065 0"
      rpy="3.1416 -0.50643 0" />
    <parent
      link="R_F_2" />
    <child
      link="R_F_lun" />
    <axis
      xyz="0 1 0" />
  </joint>
  <link
    name="R_H_1">
    <inertial>
      <origin
        xyz="0.0200809690208488 0.00243813211080819 1.38777878078145E-17"
        rpy="0 0 0" />
      <mass
        value="0.0103010381319344" />
      <inertia
        ixx="7.46635077822691E-07"
        ixy="1.9067502731996E-08"
        ixz="1.85288457211878E-22"
        iyy="5.0152786859681E-06"
        iyz="9.17418000394433E-23"
        izz="4.31106087412846E-06" />
    </inertial>
    <visual>
      <origin
        xyz="0 0 0"
        rpy="0 0 0" />
      <geometry>
        <mesh
          filename="package://Shuangzulun/meshes/R_H_1.STL" />
      </geometry>
      <material
        name="">
        <color
          rgba="1 1 1 1" />
      </material>
    </visual>
    <collision>
      <origin
        xyz="0 0 0"
        rpy="0 0 0" />
      <geometry>
        <mesh
          filename="package://Shuangzulun/meshes/R_H_1.STL" />
      </geometry>
    </collision>
  </link>
  <joint
    name="R_H_1"
    type="continuous">
    <origin
      xyz="-0.0665 0.03 0.034"
      rpy="0 0.4364 1.5708" />
    <parent
      link="base_link" />
    <child
      link="R_H_1" />
    <axis
      xyz="0 1 0" />
  </joint>
  <link
    name="R_H_2">
    <inertial>
      <origin
        xyz="0.0579756907615446 -0.00265632955087525 -1.16470889280351E-06"
        rpy="0 0 0" />
      <mass
        value="0.0152703665823153" />
      <inertia
        ixx="7.68376495458805E-07"
        ixy="1.4296118469073E-08"
        ixz="1.17880192616807E-08"
        iyy="2.01064464712029E-05"
        iyz="4.16136337057775E-13"
        izz="1.94031525718368E-05" />
    </inertial>
    <visual>
      <origin
        xyz="0 0 0"
        rpy="0 0 0" />
      <geometry>
        <mesh
          filename="package://Shuangzulun/meshes/R_H_2.STL" />
      </geometry>
      <material
        name="">
        <color
          rgba="1 1 1 1" />
      </material>
    </visual>
    <collision>
      <origin
        xyz="0 0 0"
        rpy="0 0 0" />
      <geometry>
        <mesh
          filename="package://Shuangzulun/meshes/R_H_2.STL" />
      </geometry>
    </collision>
  </link>
  <joint
    name="R_H_2"
    type="continuous">
    <origin
      xyz="0.05 0.006 0"
      rpy="0 1.1924 3.1416" />
    <parent
      link="R_H_1" />
    <child
      link="R_H_2" />
    <axis
      xyz="0 1 0" />
  </joint>
  <link
    name="R_H_lun">
    <inertial>
      <origin
        xyz="0.0147362939084086 -0.0948802665650717 0.0573291431396988"
        rpy="0 0 0" />
      <mass
        value="0.0382346146678116" />
      <inertia
        ixx="7.29879580972196E-06"
        ixy="-7.22035508470371E-11"
        ixz="-4.57836061297634E-10"
        iyy="1.22053148780522E-05"
        iyz="-6.01093343182056E-10"
        izz="7.29458621985725E-06" />
    </inertial>
    <visual>
      <origin
        xyz="0 0 0"
        rpy="0 0 0" />
      <geometry>
        <mesh
          filename="package://Shuangzulun/meshes/R_H_lun.STL" />
      </geometry>
      <material
        name="">
        <color
          rgba="0.298039215686275 0.298039215686275 0.298039215686275 1" />
      </material>
    </visual>
    <collision>
      <origin
        xyz="0 0 0"
        rpy="0 0 0" />
      <geometry>
        <mesh
          filename="package://Shuangzulun/meshes/R_H_lun.STL" />
      </geometry>
    </collision>
  </link>
  <joint
    name="R_H_lun"
    type="continuous">
    <origin
      xyz="0.063622 0.0725 0.042308"
      rpy="3.1416 1.0259 3.1416" />
    <parent
      link="R_H_2" />
    <child
      link="R_H_lun" />
    <axis
      xyz="0 1 0" />
  </joint>
</robot>