#VRML_SIM R2023b utf8

EXTERNPROTO "https://raw.githubusercontent.com/cyberbotics/webots/R2023b/projects/objects/backgrounds/protos/TexturedBackground.proto"
EXTERNPROTO "https://raw.githubusercontent.com/cyberbotics/webots/R2023b/projects/objects/backgrounds/protos/TexturedBackgroundLight.proto"
EXTERNPROTO "https://raw.githubusercontent.com/cyberbotics/webots/R2023b/projects/objects/floors/protos/Floor.proto"

WorldInfo {
  basicTimeStep 1
}
Viewpoint {
  orientation 0.2117382771077205 -0.06405558855121275 -0.9752249912624327 3.759185298831651
  position 2.3530095496457806 -0.8529163997190132 1.2688414752640194
}
TexturedBackground {
}
TexturedBackgroundLight {
}
Floor {
}
Robot {
  translation 0.00633671 -0.126261 0.130837
  rotation 0.025276800515083662 -0.006551820133511182 0.9996590203707756 0.039211
  children [
    DEF Body Pose {
      children [
        Gyro {
        }
        InertialUnit {
          name "my_imu"
        }
        DEF 右后腿 Pose {
          translation 0.07 -0.03 0
          children [
            DEF 右后大腿电机 HingeJoint {
              jointParameters HingeJointParameters {
                position 0.004660661404319418
              }
              device [
                PositionSensor {
                  name "R_H_S_da"
                }
                RotationalMotor {
                  name "R_H_M_da"
                }
              ]
              endPoint Solid {
                translation 5.130756930427017e-13 -0.01759741261196585 -0.01776219775816678
                rotation 1 -7.216831469050364e-11 -3.746990459135712e-11 0.7900596614045163
                children [
                  DEF 右后小腿 Pose {
                    translation 0.01 -0.025 0
                    rotation 1 0 0 1.497668
                    children [
                      DEF 右后小腿电机 HingeJoint {
                        jointParameters HingeJointParameters {
                          position -0.0021074115564570436
                        }
                        endPoint Solid {
                          rotation -1 0 0 1.5729027187360425
                          children [
                            DEF 右后小腿外形 Pose {
                              translation 0 0 -0.05
                              rotation 1 0 0 1.570797
                              children [
                                DEF 右后小腿实际外形 Shape {
                                  appearance Appearance {
                                    material Material {
                                      ambientIntensity 0.5
                                      diffuseColor 1 1 1
                                    }
                                  }
                                  geometry Box {
                                    size 0.01 0.1 0.01
                                  }
                                }
                              ]
                            }
                            DEF 右车轮 Pose {
                              translation -0.01 0 -0.1
                              rotation -0.357405946367489 0.8628568705192763 -0.357405946367489 1.71777
                              children [
                                HingeJoint {
                                  jointParameters HingeJointParameters {
                                    position -7.92058558685777
                                    axis 0 0 1
                                  }
                                  device [
                                    RotationalMotor {
                                      name "R_H_M_lun"
                                      maxVelocity 100
                                      maxTorque 100
                                    }
                                    PositionSensor {
                                      name "R_H_S_lun"
                                    }
                                  ]
                                  endPoint Solid {
                                    rotation 0 0 1 4.645785027501403
                                    children [
                                      DEF 右车轮外形 Pose {
                                        children [
                                          Shape {
                                            appearance PBRAppearance {
                                              baseColorMap ImageTexture {
                                                url [
                                                  "C:/Users/奇怪的桃鸢/Desktop/底图.jpg"
                                                ]
                                              }
                                              metalness 0
                                            }
                                            geometry Cylinder {
                                              height 0.01
                                              radius 0.02
                                            }
                                          }
                                        ]
                                      }
                                    ]
                                    name "右车轮铰链"
                                    boundingObject USE 右车轮外形
                                    physics Physics {
                                    }
                                  }
                                }
                              ]
                            }
                          ]
                          name "右后小腿车轮铰接"
                          boundingObject USE 右后小腿外形
                          physics Physics {
                          }
                        }
                      }
                    ]
                  }
                  DEF 右后大腿外形 Pose {
                    rotation 1 0 0 0
                    children [
                      DEF 右后大腿实际外形 Shape {
                        appearance Appearance {
                          material Material {
                            ambientIntensity 0.4
                            diffuseColor 1 0 1
                          }
                        }
                        geometry Box {
                          size 0.01 0.05 0.01
                        }
                      }
                    ]
                  }
                ]
                boundingObject USE 右后大腿实际外形
                physics Physics {
                }
              }
            }
          ]
        }
        DEF 左后腿 Pose {
          translation -0.07 -0.03 0
          children [
            DEF 左后大腿电机 HingeJoint {
              jointParameters HingeJointParameters {
                position 0.0046606615040310296
              }
              device [
                PositionSensor {
                  name "L_H_S_da"
                }
                RotationalMotor {
                  name "L_H_M_da"
                }
              ]
              endPoint Solid {
                translation -5.131034486183229e-13 -0.017597412610195116 -0.01776219775992188
                rotation 0.9999999999999999 7.216839508747871e-11 3.74699416672647e-11 0.7900596615042303
                children [
                  DEF 左后小腿 Pose {
                    translation -0.01 -0.025 0
                    rotation 1 0 0 1.497668
                    children [
                      DEF 左后小腿电机 HingeJoint {
                        jointParameters HingeJointParameters {
                          position -0.002082393151234263
                        }
                        endPoint Solid {
                          rotation -1 0 0 1.5728777003308192
                          children [
                            DEF 左后小腿外形 Pose {
                              translation 0 0 -0.05
                              rotation 1 0 0 1.570797
                              children [
                                DEF 左后小腿实际外形 Shape {
                                  appearance Appearance {
                                    material Material {
                                      ambientIntensity 0.5
                                      diffuseColor 1 1 1
                                    }
                                  }
                                  geometry Box {
                                    size 0.01 0.1 0.01
                                  }
                                }
                              ]
                            }
                            DEF 左车轮 Pose {
                              translation 0.01 5.42964e-09 -0.1
                              rotation -0.357405946367489 0.8628568705192763 -0.357405946367489 1.71777
                              children [
                                HingeJoint {
                                  jointParameters HingeJointParameters {
                                    position -8.703030431037128
                                    axis 0 0 1
                                  }
                                  device [
                                    RotationalMotor {
                                      name "L_H_M_lun"
                                      maxVelocity 100
                                    }
                                    PositionSensor {
                                      name "L_H_S_lun"
                                    }
                                  ]
                                  endPoint Solid {
                                    rotation 0 0 1 3.863340183322045
                                    children [
                                      DEF 左车轮外形 Pose {
                                        children [
                                          Shape {
                                            appearance PBRAppearance {
                                              baseColorMap ImageTexture {
                                                url [
                                                  "C:/Users/奇怪的桃鸢/Desktop/底图.jpg"
                                                ]
                                              }
                                            }
                                            geometry Cylinder {
                                              height 0.01
                                              radius 0.02
                                            }
                                          }
                                        ]
                                      }
                                    ]
                                    name "左车轮铰链"
                                    boundingObject USE 左车轮外形
                                    physics Physics {
                                    }
                                  }
                                }
                              ]
                            }
                          ]
                          name "左后小腿车轮铰接"
                          boundingObject USE 左后小腿外形
                          physics Physics {
                          }
                        }
                      }
                    ]
                  }
                  DEF 左后大腿外形 Pose {
                    rotation 1 0 0 0
                    children [
                      DEF 左后大腿实际外形 Shape {
                        appearance Appearance {
                          material Material {
                            ambientIntensity 0.4
                            diffuseColor 1 0.333333 1
                          }
                        }
                        geometry Box {
                          size 0.01 0.05 0.01
                        }
                      }
                    ]
                  }
                ]
                name "solid(2)"
                boundingObject USE 左后大腿实际外形
                physics Physics {
                }
              }
            }
          ]
        }
        DEF 右前腿 Pose {
          translation 0.07 0.03 0
          rotation 1 0 0 1.5708
          children [
            DEF 右前大腿电机 HingeJoint {
              jointParameters HingeJointParameters {
                position 0.004715974776365995
              }
              device [
                PositionSensor {
                  name "R_F_S_da"
                }
                RotationalMotor {
                  name "R_F_M_da"
                }
              ]
              endPoint Solid {
                translation 3.9872272150631665e-13 -0.017596412355898802 -0.01776318623801076
                rotation 1 1.1016573231110468e-10 1.0464867452690677e-10 0.790114974775728
                children [
                  DEF 右前小腿 Pose {
                    translation 0.02 -0.025 0
                    rotation 1 0 0 -1.49767
                    children [
                      DEF 右前小腿电机 HingeJoint {
                        jointParameters HingeJointParameters {
                          position -0.002193730746780199
                        }
                        endPoint Solid {
                          rotation -0.9999999999999999 0 0 1.5729890379263625
                          children [
                            DEF 右轮铰链位置 Pose {
                              translation 0 0 -0.1
                              children [
                                DEF 右前轮铰链 HingeJoint {
                                  jointParameters HingeJointParameters {
                                    position 3.10057543754412e-05
                                  }
                                  endPoint SolidReference {
                                    solidName "右后小腿车轮铰接"
                                  }
                                }
                              ]
                            }
                            DEF 右前小腿外形 Pose {
                              translation 0 0 -0.05
                              rotation 1 0 0 1.570797
                              children [
                                DEF 右后小腿实际外形 Shape {
                                  appearance Appearance {
                                    material Material {
                                      ambientIntensity 0.5
                                      diffuseColor 1 1 1
                                    }
                                  }
                                  geometry Box {
                                    size 0.01 0.1 0.01
                                  }
                                }
                              ]
                            }
                          ]
                          boundingObject USE 右前小腿外形
                          physics Physics {
                          }
                        }
                      }
                    ]
                  }
                  DEF 右前大腿外形 Pose {
                    translation 0.005 0 0
                    rotation 1 0 0 0
                    children [
                      DEF 右后大腿实际外形 Shape {
                        appearance Appearance {
                          material Material {
                            ambientIntensity 0.4
                            diffuseColor 1 0.333333 1
                          }
                        }
                        geometry Box {
                          size 0.02 0.05 0.01
                        }
                      }
                    ]
                  }
                ]
                name "solid(1)"
                boundingObject USE 右后大腿实际外形
                physics Physics {
                }
              }
            }
          ]
        }
        DEF 左前腿 Pose {
          translation -0.07 0.03 0
          rotation 1 0 0 1.5708
          children [
            DEF 左前大腿电机 HingeJoint {
              jointParameters HingeJointParameters {
                position 0.004715974679788459
              }
              device [
                PositionSensor {
                  name "L_F_S_da"
                }
                RotationalMotor {
                  name "L_F_M_da"
                }
              ]
              endPoint Solid {
                translation -3.9872272150631817e-13 -0.017596412357614246 -0.017763186236311745
                rotation 1 -1.101657311363837e-10 -1.0464867429214858e-10 0.7901149746791499
                children [
                  DEF 左前小腿 Pose {
                    translation -0.02 -0.025 0
                    rotation 1 0 0 -1.49767
                    children [
                      DEF 左前小腿电机 HingeJoint {
                        jointParameters HingeJointParameters {
                          position -0.00222285217320408
                        }
                        endPoint Solid {
                          rotation -0.9999999999999999 0 0 1.573018159352788
                          children [
                            DEF 左轮铰链位置 Pose {
                              translation 0 0 -0.1
                              children [
                                DEF 左前轮铰链 HingeJoint {
                                  jointParameters HingeJointParameters {
                                    position 8.514587810998231e-05
                                  }
                                  endPoint SolidReference {
                                    solidName "左后小腿车轮铰接"
                                  }
                                }
                              ]
                            }
                            DEF 左前小腿外形 Pose {
                              translation 0 0 -0.05
                              rotation 1 0 0 1.570797
                              children [
                                DEF 左后小腿实际外形 Shape {
                                  appearance Appearance {
                                    material Material {
                                      ambientIntensity 0.5
                                      diffuseColor 1 1 1
                                    }
                                  }
                                  geometry Box {
                                    size 0.01 0.1 0.01
                                  }
                                }
                              ]
                            }
                          ]
                          boundingObject USE 左前小腿外形
                          physics Physics {
                          }
                        }
                      }
                    ]
                  }
                  DEF 左前大腿外形 Pose {
                    translation -0.005 0 0
                    rotation 1 0 0 0
                    children [
                      DEF 左后大腿实际外形 Shape {
                        appearance Appearance {
                          material Material {
                            ambientIntensity 0.4
                            diffuseColor 1 0.333333 1
                          }
                        }
                        geometry Box {
                          size 0.02 0.05 0.01
                        }
                      }
                    ]
                  }
                ]
                name "solid(3)"
                boundingObject USE 左后大腿实际外形
                physics Physics {
                }
              }
            }
          ]
        }
        DEF Body实际外形 Shape {
          appearance Appearance {
            material Material {
              ambientIntensity 0.4
              diffuseColor 0.333333 0.666667 1
            }
          }
          geometry Box {
            size 0.13 0.12 0.07
          }
        }
      ]
    }
  ]
  boundingObject USE Body实际外形
  physics Physics {
  }
  controller "lun_controller"
  supervisor TRUE
}
DEF 斜面 Solid {
  translation -0.489648 0 0.0386406
  rotation 0 1 0 0.261794
  children [
    DEF 地形 Shape {
      appearance Appearance {
        material Material {
          diffuseColor 1 1 0.498039
        }
      }
      geometry Box {
        size 0.7 1 0.1
      }
    }
  ]
  boundingObject USE 地形
}
DEF 凹凸地形 Solid {
  translation 0.04 -2.9 -1.06515e-05
  rotation 1 0 0 1.5708
  children [
    DEF 凹凸地形 Shape {
      appearance Appearance {
        material Material {
          diffuseColor 1 1 0.498039
        }
      }
      geometry Mesh {
        url [
          "../SW_model/地形.STL"
        ]
      }
    }
  ]
  name "solid(1)"
  boundingObject USE 凹凸地形
}
DEF 凹凸地形1 Solid {
  translation 0.12 2.73 8.98563e-06
  rotation 3.3905113482557537e-09 0.70710528118436 0.707108281185553 3.14159
  children [
    DEF 凹凸地形 Shape {
      appearance Appearance {
        material Material {
          diffuseColor 1 1 0.498039
        }
      }
      geometry Mesh {
        url [
          "../SW_model/地形.STL"
        ]
      }
    }
  ]
  name "solid(2)"
  boundingObject USE 凹凸地形
}
DEF 凹凸地形2 Solid {
  translation 0.28 0.72 2.64463e-06
  rotation 1 0 0 1.5708
  children [
    DEF 凹凸地形 Shape {
      appearance Appearance {
        material Material {
          diffuseColor 1 1 0.498039
        }
      }
      geometry Mesh {
        url [
          "../SW_model/地形.STL"
        ]
      }
    }
  ]
  name "solid(3)"
  boundingObject USE 凹凸地形
}
